[2024-12-29 13:05:45,913] {taskinstance.py:903} INFO - Dependencies all met for <TaskInstance: agile_data_science_batch_prediction_model_training.pyspark_train_classifier_model 2024-12-29T13:00:42.288702+00:00 [queued]>
[2024-12-29 13:05:45,930] {taskinstance.py:903} INFO - Dependencies all met for <TaskInstance: agile_data_science_batch_prediction_model_training.pyspark_train_classifier_model 2024-12-29T13:00:42.288702+00:00 [queued]>
[2024-12-29 13:05:45,931] {taskinstance.py:1095} INFO - 
--------------------------------------------------------------------------------
[2024-12-29 13:05:45,931] {taskinstance.py:1096} INFO - Starting attempt 2 of 4
[2024-12-29 13:05:45,932] {taskinstance.py:1097} INFO - 
--------------------------------------------------------------------------------
[2024-12-29 13:05:45,938] {taskinstance.py:1115} INFO - Executing <Task(BashOperator): pyspark_train_classifier_model> on 2024-12-29T13:00:42.288702+00:00
[2024-12-29 13:05:45,943] {standard_task_runner.py:52} INFO - Started process 348 to run task
[2024-12-29 13:05:45,950] {standard_task_runner.py:76} INFO - Running: ['***', 'tasks', 'run', 'agile_data_science_batch_prediction_model_training', 'pyspark_train_classifier_model', '2024-12-29T13:00:42.288702+00:00', '--job-id', '68', '--pool', 'default_pool', '--raw', '--subdir', 'DAGS_FOLDER/setup.py', '--cfg-path', '/tmp/tmpc5r30l52', '--error-file', '/tmp/tmp32_gdj0u']
[2024-12-29 13:05:45,965] {standard_task_runner.py:77} INFO - Job 68: Subtask pyspark_train_classifier_model
[2024-12-29 13:05:46,012] {logging_mixin.py:109} INFO - Running <TaskInstance: agile_data_science_batch_prediction_model_training.pyspark_train_classifier_model 2024-12-29T13:00:42.288702+00:00 [running]> on host f84ed4b3915c
[2024-12-29 13:05:46,061] {taskinstance.py:1254} INFO - Exporting the following env vars:
AIRFLOW_CTX_DAG_OWNER=***
AIRFLOW_CTX_DAG_ID=agile_data_science_batch_prediction_model_training
AIRFLOW_CTX_TASK_ID=pyspark_train_classifier_model
AIRFLOW_CTX_EXECUTION_DATE=2024-12-29T13:00:42.288702+00:00
AIRFLOW_CTX_DAG_RUN_ID=manual__2024-12-29T13:00:42.288702+00:00
[2024-12-29 13:05:46,063] {subprocess.py:52} INFO - Tmp dir root location: 
 /tmp
[2024-12-29 13:05:46,065] {subprocess.py:63} INFO - Running command: ['bash', '-c', '\nspark-submit --master local[8]   None//resources/train_spark_mllib_model.py   None/']
[2024-12-29 13:05:46,071] {subprocess.py:74} INFO - Output:
[2024-12-29 13:05:47,006] {subprocess.py:78} INFO - WARNING: An illegal reflective access operation has occurred
[2024-12-29 13:05:47,007] {subprocess.py:78} INFO - WARNING: Illegal reflective access by org.apache.spark.unsafe.Platform (file:/opt/spark-3.0.0-bin-hadoop3.2/jars/spark-unsafe_2.12-3.0.0.jar) to constructor java.nio.DirectByteBuffer(long,int)
[2024-12-29 13:05:47,008] {subprocess.py:78} INFO - WARNING: Please consider reporting this to the maintainers of org.apache.spark.unsafe.Platform
[2024-12-29 13:05:47,008] {subprocess.py:78} INFO - WARNING: Use --illegal-access=warn to enable warnings of further illegal reflective access operations
[2024-12-29 13:05:47,009] {subprocess.py:78} INFO - WARNING: All illegal access operations will be denied in a future release
[2024-12-29 13:05:47,293] {subprocess.py:78} INFO - 24/12/29 13:05:47 WARN NativeCodeLoader: Unable to load native-hadoop library for your platform... using builtin-java classes where applicable
[2024-12-29 13:05:47,518] {subprocess.py:78} INFO - python: can't open file '/tmp/***tmpoaefsm6f/None/resources/train_spark_mllib_model.py': [Errno 2] No such file or directory
[2024-12-29 13:05:47,526] {subprocess.py:78} INFO - log4j:WARN No appenders could be found for logger (org.apache.spark.util.ShutdownHookManager).
[2024-12-29 13:05:47,527] {subprocess.py:78} INFO - log4j:WARN Please initialize the log4j system properly.
[2024-12-29 13:05:47,527] {subprocess.py:78} INFO - log4j:WARN See http://logging.apache.org/log4j/1.2/faq.html#noconfig for more info.
[2024-12-29 13:05:47,545] {subprocess.py:82} INFO - Command exited with return code 2
[2024-12-29 13:05:47,553] {taskinstance.py:1463} ERROR - Task failed with exception
Traceback (most recent call last):
  File "/home/airflow/.local/lib/python3.6/site-packages/airflow/models/taskinstance.py", line 1165, in _run_raw_task
    self._prepare_and_execute_task_with_callbacks(context, task)
  File "/home/airflow/.local/lib/python3.6/site-packages/airflow/models/taskinstance.py", line 1283, in _prepare_and_execute_task_with_callbacks
    result = self._execute_task(context, task_copy)
  File "/home/airflow/.local/lib/python3.6/site-packages/airflow/models/taskinstance.py", line 1313, in _execute_task
    result = task_copy.execute(context=context)
  File "/home/airflow/.local/lib/python3.6/site-packages/airflow/operators/bash.py", line 176, in execute
    raise AirflowException('Bash command failed. The command returned a non-zero exit code.')
airflow.exceptions.AirflowException: Bash command failed. The command returned a non-zero exit code.
[2024-12-29 13:05:47,556] {taskinstance.py:1513} INFO - Marking task as UP_FOR_RETRY. dag_id=agile_data_science_batch_prediction_model_training, task_id=pyspark_train_classifier_model, execution_date=20241229T130042, start_date=20241229T130545, end_date=20241229T130547
[2024-12-29 13:05:47,608] {local_task_job.py:151} INFO - Task exited with return code 1
[2024-12-29 13:05:47,624] {local_task_job.py:261} INFO - 0 downstream tasks scheduled from follow-on schedule check
